Workbook
Name ABRILPLUS: '[3]TP ABRIL'!$A$8:$O$78
Name canal24h: '[4]Tarifas Marzo 2009 v22'!$C$8:$N$105
Name CENTRAL2: [4]Rating!$K$12:$L$19
Name COL: [5]COL!$C$5:$D$16
Name colu2: [3]COL!$F$5:$G$17
Name colu24: [6]Hoja1!$B$11:$C$21
Name COLUMNAS: '[4]Tarifas Marzo 2009 v22'!$P$8:$Q$19
Name COLUMNASTARGET: [3]bases!$E$9:$F$30
Name DF: [7]COL!$C$5:$D$16
Name efinal: [8]RANGOS!$K$6:$K$11
Name einicial: [8]RANGOS!$J$6:$J$11
Name GRPSPAUTAS: '[3]Pautas 24 horas'!$R$13:$BF$32
Name GSEDDC: [5]DatosTP!$J$32:$K$41
Name HDM: [4]Rating!$K$35:$L$41
Name horasdia: [4]Rating!$K$5:$L$10
Name junio: [9]DatosRM!$A$7:$O$89
Name NIVELABRIL: '[3]Niveles ABRIL'!$A$7:$B$76
Name notcom: [5]Rating1!$J$12:$L$19
Name noviembr: [7]codigos!$A$7:$B$94
Name parrilla: #REF!
Name PARRILLA1: #REF!
Name PAUTA: [5]Pauta!$B$20:$AV$95
Name plus: '[10]Tarifa PLUS'!$A$8:$O$19
Name plusdic: '[5]Tarifa PLUS'!$A$7:$O$21
Name porcentaje: [6]bases!$E$9:$G$30
Name porcentajeprime: [3]bases!$E$9:$G$34
Name RATI2: [11]Rating1!$J$4:$K$117
Name rating1: '[8]Rat M25-64C2C3'!$H$3:$I$375
Name rating2: '[8]Rat H25-64ABCD'!$H$1:$I$288
Name rating3: '[8]Rat HM18-24ABC'!$H$2:$I$290
Name rating4: '[8]Rat HM25-49ABC1C2'!$H$3:$I$246
Name rating5: '[8]Rat HM25-64ABC'!$H$3:$I$309
Name rating6: '[8]Rat M25-64ABC'!$H$2:$I$333
Name rating7: '[8]Rat HM25-64ABCD'!$H$3:$I$210
Name ratings: [4]Rating!$H$3:$I$1175
Name ratingstarget: [8]RANGOS!$D$6:$F$18
Name regiones1: '[12]Tarifas Febrero 2013'!$B$3:$BD$58
Name regiones2: '[12]Tarifas Febrero 2013'!$B$70:$BL$128
Name regmet: [13]DatosTP!$C$5:$K$27
Name REGMETGSE: [13]DatosTP!$D$32:$E$41
Name resrat: '[8]res rat'!$C$2:$J$1348
Name RMDDC: [5]DatosRM!$C$4:$M$27
Name septiembre: '[7]2015 Netas'!$G$4:$T$60
Name tarifas24h: [3]bases!$C$37:$N$39
Name tarifas24horas: '[3]Tarifas Canal 24H'!$B$8:$M$9
Name trasnoche1: [14]Rating1!$J$22:$K$34

Sheet CHV
A1: Cliente | B1: COMPARA
A2: Agencia | B2: FORZA
A3: Fecha | B3: 21.09.2026
A4: Contacto | B4: SEBA PADILLA
A5: Validez | B5: OCTUBRE
B8: PRECIOS PAUTA OCTUBRE 2026 | L8: VALORES CON DESCUENTO NETOS
B9: BLOQUE | C9: PROGRAMA | D9: DIA | E9: HRA | F9: CLASIF | G9: TARIFA TI | I9: Unitario 70" | J9: Bloque | K9: Rating | L9: Valor 60 segundos | M9: Valor 55 segundos | N9: Valor 50 segundos | O9: Valor 45 segundos | P9: Valor 40 segundos | Q9: Valor 35 segundos | R9: Valor 30 segundos | S9: Valor 25 segundos | T9: Valor 20 segundos | U9: Valor 15 segundos | V9: Valor 10 segundos | W9: Valor 5 segundos
B10: Off | C10: Chv Noticias AM Contigo | D10: LMWJV | E10: 0.32291667 | F10: P73 | G10: 651142.61 | H10: 0.7 | J10: Off | K10: 0.88096976 | L10: =R10*2.33 -> 455148.69 | M10: =R10*2.04 -> 398499.28 | N10: =R10*1.77 -> 345756.73 | O10: =R10*1.51 -> 294967.6 | P10: =R10*1.34 -> 261759.33 | Q10: =R10*1.17 -> 228551.06 | R10: =G10*(1-H10) -> 195342.78 | S10: =R10*0.93 -> 181668.79 | T10: =R10*0.85 -> 166041.37 | U10: =R10*0.75 -> 146507.09 | V10: =R10*0.6 -> 117205.67 | W10: =R10*0.36 -> 70323.402
B11: Off | C11: Contigo en La Mañana A | D11: LMWJV | E11: 08:00 a 11:30 | F11: P87 | G11: 1289217.8 | H11: 0.7 | J11: Off | K11: 1.8710094 | L11: =R11*2.33 -> 901163.26 | M11: =R11*2.04 -> 789001.31 | N11: =R11*1.77 -> 684574.67 | O11: =R11*1.51 -> 584015.68 | P11: =R11*1.34 -> 518265.57 | Q11: =R11*1.17 -> 452515.46 | R11: =G11*(1-H11) -> 386765.35 | S11: =R11*0.93 -> 359691.78 | T11: =R11*0.85 -> 328750.55 | U11: =R11*0.75 -> 290074.01 | V11: =R11*0.6 -> 232059.21 | W11: =R11*0.36 -> 139235.53
B12: Off | C12: Contigo en La Mañana B | D12: LMWJV | E12: 11:30 a 13:00 | F12: P87 | G12: 1289217.8 | H12: 0.7 | J12: Off | K12: 1.9030263 | L12: =R12*2.33 -> 901163.26 | M12: =R12*2.04 -> 789001.31 | N12: =R12*1.77 -> 684574.67 | O12: =R12*1.51 -> 584015.68 | P12: =R12*1.34 -> 518265.57 | Q12: =R12*1.17 -> 452515.46 | R12: =G12*(1-H12) -> 386765.35 | S12: =R12*0.93 -> 359691.78 | T12: =R12*0.85 -> 328750.55 | U12: =R12*0.75 -> 290074.01 | V12: =R12*0.6 -> 232059.21 | W12: =R12*0.36 -> 139235.53
B13: Off | C13: Chv Noticias Tarde | D13: LMWJV | E13: 0.54166667 | F13: P92 | G13: 1645404.9 | H13: 0.7 | J13: Off | K13: 2.3556206 | L13: =R13*2.33 -> 1150138.1 | M13: =R13*2.04 -> 1006987.8 | N13: =R13*1.77 -> 873710.03 | O13: =R13*1.51 -> 745368.44 | P13: =R13*1.34 -> 661452.79 | Q13: =R13*1.17 -> 577537.14 | R13: =G13*(1-H13) -> 493621.48 | S13: =R13*0.93 -> 459067.98 | T13: =R13*0.85 -> 419578.26 | U13: =R13*0.75 -> 370216.11 | V13: =R13*0.6 -> 296172.89 | W13: =R13*0.36 -> 177703.73
B14: Off | C14: Contigo en Directo | D14: LMWJV | E14: 0.64583333 | F14: P87 | G14: 1289217.8 | H14: 0.7 | J14: Off | K14: 2.3479629 | L14: =R14*2.33 -> 901163.26 | M14: =R14*2.04 -> 789001.31 | N14: =R14*1.77 -> 684574.67 | O14: =R14*1.51 -> 584015.68 | P14: =R14*1.34 -> 518265.57 | Q14: =R14*1.17 -> 452515.46 | R14: =G14*(1-H14) -> 386765.35 | S14: =R14*0.93 -> 359691.78 | T14: =R14*0.85 -> 328750.55 | U14: =R14*0.75 -> 290074.01 | V14: =R14*0.6 -> 232059.21 | W14: =R14*0.36 -> 139235.53
B15: Off | C15: Plan Perfecto | D15: LMWJV | E15: 0.70833333 | F15: P89 | G15: 1421362.7 | H15: 0.7 | J15: Off | K15: 2.1397667 | L15: =R15*2.33 -> 993532.5 | M15: =R15*2.04 -> 869873.95 | N15: =R15*1.77 -> 754743.57 | O15: =R15*1.51 -> 643877.29 | P15: =R15*1.34 -> 571387.79 | Q15: =R15*1.17 -> 498898.29 | R15: =G15*(1-H15) -> 426408.8 | S15: =R15*0.93 -> 396560.18 | T15: =R15*0.85 -> 362447.48 | U15: =R15*0.75 -> 319806.6 | V15: =R15*0.6 -> 255845.28 | W15: =R15*0.36 -> 153507.17
B16: Prime | C16: Chv Noticias Central | D16: LMWJV | E16: 0.85416667 | F16: P107 | G16: 3420678.7 | H16: 0.65 | J16: Prime time | K16: 2.8291209 | L16: =R16*2.33 -> 2789563.5 | M16: =R16*2.04 -> 2442364.6 | N16: =R16*1.77 -> 2119110.5 | O16: =R16*1.51 -> 1807828.7 | P16: =R16*1.34 -> 1604298.3 | Q16: =R16*1.17 -> 1400767.9 | R16: =G16*(1-H16) -> 1197237.6 | S16: =R16*0.93 -> 1113430.9 | T16: =R16*0.85 -> 1017651.9 | U16: =R16*0.75 -> 897928.16 | V16: =R16*0.6 -> 718342.53 | W16: =R16*0.36 -> 431005.52
B17: Prime | C17: Chv Noticias Central | D17: S | E17: 0.85416667 | F17: P103 | G17: 2814200.8 | H17: 0.65 | J17: Prime time | K17: 2 | L17: =R17*2.33 -> 2294980.8 | M17: =R17*2.04 -> 2009339.4 | N17: =R17*1.77 -> 1743397.4 | O17: =R17*1.51 -> 1487305.1 | P17: =R17*1.34 -> 1319860.2 | Q17: =R17*1.17 -> 1152415.2 | R17: =G17*(1-H17) -> 984970.3 | S17: =R17*0.93 -> 916022.38 | T17: =R17*0.85 -> 837224.75 | U17: =R17*0.75 -> 738727.72 | V17: =R17*0.6 -> 590982.18 | W17: =R17*0.36 -> 354589.31
B18: Prime | C18: Chv Noticias Central | D18: D | E18: 0.85416667 | F18: P109 | G18: 3771298.3 | H18: 0.65 | J18: Prime time | K18: 2.8291209 | L18: =R18*2.33 -> 3075493.8 | M18: =R18*2.04 -> 2692707 | N18: =R18*1.77 -> 2336319.3 | O18: =R18*1.51 -> 1993131.1 | P18: =R18*1.34 -> 1768738.9 | Q18: =R18*1.17 -> 1544346.6 | R18: =G18*(1-H18) -> 1319954.4 | S18: =R18*0.93 -> 1227557.6 | T18: =R18*0.85 -> 1121961.2 | U18: =R18*0.75 -> 989965.8 | V18: =R18*0.6 -> 791972.64 | W18: =R18*0.36 -> 475183.58
B19: Prime | C19: Fiebre de Canto | D19: LMW | E19: 0.9375 | F19: P105 | G19: 3102656.4 | H19: 0.65 | J19: Prime time | K19: 1.8585546 | L19: =R19*2.33 -> 2530216.3 | M19: =R19*2.04 -> 2215296.7 | N19: =R19*1.77 -> 1922095.7 | O19: =R19*1.51 -> 1639753.9 | P19: =R19*1.34 -> 1455145.9 | Q19: =R19*1.17 -> 1270537.8 | R19: =G19*(1-H19) -> 1085929.8 | S19: =R19*0.93 -> 1009914.7 | T19: =R19*0.85 -> 923040.29 | U19: =R19*0.75 -> 814447.31 | V19: =R19*0.6 -> 651557.85 | W19: =R19*0.36 -> 390934.71
B20: Prime | C20: El Club de la Comedia | D20: J | E20: 0.9375 | F20: P99 | G20: 2315250 | H20: 0.67 | J20: Prime time | K20: 1.7176602 | L20: =R20*2.33 -> 1780195.7 | M20: =R20*2.04 -> 1558626.3 | N20: =R20*1.77 -> 1352337.5 | O20: =R20*1.51 -> 1153689.1 | P20: =R20*1.34 -> 1023803.5 | Q20: =R20*1.17 -> 893918.02 | R20: =G20*(1-H20) -> 764032.5 | S20: =R20*0.93 -> 710550.22 | T20: =R20*0.85 -> 649427.62 | U20: =R20*0.75 -> 573024.37 | V20: =R20*0.6 -> 458419.5 | W20: =R20*0.36 -> 275051.7
B21: Prime | C21: Primer Plano | D21: V | E21: 0.9375 | F21: P97 | G21: 2100000 | H21: 0.67 | J21: Prime time | K21: 1.7 | L21: =R21*2.33 -> 1614690 | M21: =R21*2.04 -> 1413720 | N21: =R21*1.77 -> 1226610 | O21: =R21*1.51 -> 1046430 | P21: =R21*1.34 -> 928620 | Q21: =R21*1.17 -> 810810 | R21: =G21*(1-H21) -> 693000 | S21: =R21*0.93 -> 644490 | T21: =R21*0.85 -> 589050 | U21: =R21*0.75 -> 519750 | V21: =R21*0.6 -> 415800 | W21: =R21*0.36 -> 249480
B22: Prime | C22: La Divina Comida | D22: S | E22: 0.91666667 | F22: P99 | G22: 2315250 | H22: 0.67 | J22: Prime time | K22: 1.6561442 | L22: =R22*2.33 -> 1780195.7 | M22: =R22*2.04 -> 1558626.3 | N22: =R22*1.77 -> 1352337.5 | O22: =R22*1.51 -> 1153689.1 | P22: =R22*1.34 -> 1023803.5 | Q22: =R22*1.17 -> 893918.02 | R22: =G22*(1-H22) -> 764032.5 | S22: =R22*0.93 -> 710550.22 | T22: =R22*0.85 -> 649427.62 | U22: =R22*0.75 -> 573024.37 | V22: =R22*0.6 -> 458419.5 | W22: =R22*0.36 -> 275051.7
B23: Prime | C23: Fiebre de Canto | D23: D | E23: 0.9375 | F23: P105 | G23: 3102656.4 | H23: 0.65 | J23: Prime time | K23: 1.8585546 | L23: =R23*2.33 -> 2530216.3 | M23: =R23*2.04 -> 2215296.7 | N23: =R23*1.77 -> 1922095.7 | O23: =R23*1.51 -> 1639753.9 | P23: =R23*1.34 -> 1455145.9 | Q23: =R23*1.17 -> 1270537.8 | R23: =G23*(1-H23) -> 1085929.8 | S23: =R23*0.93 -> 1009914.7 | T23: =R23*0.85 -> 923040.29 | U23: =R23*0.75 -> 814447.31 | V23: =R23*0.6 -> 651557.85 | W23: =R23*0.36 -> 390934.71
B24: Off | C24: El Var, after del Baile | D24: LMW | E24: 0.03125 | F24: P78 | G24: 831041.31 | H24: 0.7 | J24: Off | K24: 0.84076495 | L24: =R24*2.33 -> 580897.88 | M24: =R24*2.04 -> 508597.28 | N24: =R24*1.77 -> 441282.94 | O24: =R24*1.51 -> 376461.71 | P24: =R24*1.34 -> 334078.61 | Q24: =R24*1.17 -> 291695.5 | R24: =G24*(1-H24) -> 249312.39 | S24: =R24*0.93 -> 231860.53 | T24: =R24*0.85 -> 211915.53 | U24: =R24*0.75 -> 186984.29 | V24: =R24*0.6 -> 149587.44 | W24: =R24*0.36 -> 89752.461
... B27: Off | C27: Chv Noticias Tarde Sáb.Dgo. | D27: SD | E27: 0.54166667 | F27: P89 | G27: 1421362.7 | H27: 0.7 | J27: Off | K27: 2.3556206 | L27: =R27*2.33 -> 993532.5 | M27: =R27*2.04 -> 869873.95 | N27: =R27*1.77 -> 754743.57 | O27: =R27*1.51 -> 643877.29 | P27: =R27*1.34 -> 571387.79 | Q27: =R27*1.17 -> 498898.29 | R27: =G27*(1-H27) -> 426408.8 | S27: =R27*0.93 -> 396560.18 | T27: =R27*0.85 -> 362447.48 | U27: =R27*0.75 -> 319806.6 | V27: =R27*0.6 -> 255845.28 | W27: =R27*0.36 -> 153507.17
B28: Off | C28: Sabingo A | D28: SD | E28: 15:00 a 18:00 | F28: P82 | G28: 1010135.9 | H28: 0.7 | J28: Off | K28: 1.5161659 | L28: =R28*2.33 -> 706085 | M28: =R28*2.04 -> 618203.17 | N28: =R28*1.77 -> 536382.17 | O28: =R28*1.51 -> 457591.57 | P28: =R28*1.34 -> 406074.63 | Q28: =R28*1.17 -> 354557.7 | R28: =G28*(1-H28) -> 303040.77 | S28: =R28*0.93 -> 281827.92 | T28: =R28*0.85 -> 257584.66 | U28: =R28*0.75 -> 227280.58 | V28: =R28*0.6 -> 181824.46 | W28: =R28*0.36 -> 109094.68
B29: Off | C29: Sabingo B | D29: SD | E29: 18:30 a 20:30 | F29: P84 | G29: 1113674.8 | H29: 0.7 | J29: Off | K29: 1.8300043 | L29: =R29*2.33 -> 778458.71 | M29: =R29*2.04 -> 681569 | N29: =R29*1.77 -> 591361.34 | O29: =R29*1.51 -> 504494.7 | P29: =R29*1.34 -> 447697.28 | Q29: =R29*1.17 -> 390899.87 | R29: =G29*(1-H29) -> 334102.45 | S29: =R29*0.93 -> 310715.28 | T29: =R29*0.85 -> 283987.08 | U29: =R29*0.75 -> 250576.84 | V29: =R29*0.6 -> 200461.47 | W29: =R29*0.36 -> 120276.88

Sheet Mega
I2: COMPARA
B6: TARIFAS MEGA VALIDAS PARA OCTUBRE 2026
G7: 0.38 | H7: 0.64 | I7: 0.77 | J7: 0.87 | K7: 0.92 | L7: 1 | M7: 1.17 | N7: 1.35 | O7: 1.57 | P7: 1.82 | Q7: 2.12 | R7: 2.4
G8: 0.38 | H8: 0.64 | I8: 0.77 | J8: 0.87 | K8: 0.92 | L8: 1 | M8: 1.17 | N8: 1.35 | O8: 1.57 | P8: 1.82 | Q8: 2.12 | R8: 2.4
G10: 5 | H10: 10 | I10: 15 | J10: 20 | K10: 25 | L10: 30 | M10: 35 | N10: 40 | O10: 45 | P10: 50 | Q10: 55 | R10: 60
B11: PROGRAMA | C11: DÍAS | D11: HORARIO | E11: BLOQUE | F11: RATING | G11: Valor 5 | H11: Valor 10 | I11: Valor 15 | J11: Valor 20 | K11: Valor 25 | L11: Valor 30 | M11: Valor 35 | N11: Valor 40 | O11: Valor 45 | P11: Valor 50 | Q11: Valor 55 | R11: Valor 60
B12: MEGANOTICIAS AMANECE | C12: L-V | D12: 05:45-08:00 | E12: Off | F12: 0.94 | G12: =L12*$G$8 -> 54720 | H12: =L12*$H$8 -> 92160 | I12: =L12*$I$8 -> 110880 | J12: =L12*$J$8 -> 125280 | K12: =L12*$K$8 -> 132480 | L12: 144000 | M12: =L12*$M$8 -> 168480 | N12: =L12*$N$8 -> 194400 | O12: =L12*$O$8 -> 226080 | P12: =L12*$P$8 -> 262080 | Q12: =L12*$Q$8 -> 305280 | R12: =L12*$R$8 -> 345600
B13: MUCHO GUSTO | C13: L-V | D13: 08:00-13:00 | E13: Off | F13: 2.6914646 | G13: =L13*$G$8 -> 206720 | H13: =L13*$H$8 -> 348160 | I13: =L13*$I$8 -> 418880 | J13: =L13*$J$8 -> 473280 | K13: =L13*$K$8 -> 500480 | L13: 544000 | M13: =L13*$M$8 -> 636480 | N13: =L13*$N$8 -> 734400 | O13: =L13*$O$8 -> 854080 | P13: =L13*$P$8 -> 990080 | Q13: =L13*$Q$8 -> 1153280 | R13: =L13*$R$8 -> 1305600
B14: MEGANOTICIAS ALERTA SEMANA | C14: L-V | D14: 13:00-15:00 | E14: Off | F14: 3.2579054 | G14: =L14*$G$8 -> 194560 | H14: =L14*$H$8 -> 327680 | I14: =L14*$I$8 -> 394240 | J14: =L14*$J$8 -> 445440 | K14: =L14*$K$8 -> 471040 | L14: 512000 | M14: =L14*$M$8 -> 599040 | N14: =L14*$N$8 -> 691200 | O14: =L14*$O$8 -> 803840 | P14: =L14*$P$8 -> 931840 | Q14: =L14*$Q$8 -> 1085440 | R14: =L14*$R$8 -> 1228800
B15: LA HORA DE JUGAR | C15: L-V | D15: 15:00-15:45 | E15: Off | F15: 2.3897059 | G15: =L15*$G$8 -> 162640 | H15: =L15*$H$8 -> 273920 | I15: =L15*$I$8 -> 329560 | J15: =L15*$J$8 -> 372360 | K15: =L15*$K$8 -> 393760 | L15: 428000 | M15: =L15*$M$8 -> 500760 | N15: =L15*$N$8 -> 577800 | O15: =L15*$O$8 -> 671960 | P15: =L15*$P$8 -> 778960 | Q15: =L15*$Q$8 -> 907360 | R15: =L15*$R$8 -> 1027200
B16: CARMEN GLORIA FUERTE Y CLARO | C16: L-V | D16: 15:45-16:45 | E16: Off | F16: 2.4226804 | G16: =L16*$G$8 -> 170240 | H16: =L16*$H$8 -> 286720 | I16: =L16*$I$8 -> 344960 | J16: =L16*$J$8 -> 389760 | K16: =L16*$K$8 -> 412160 | L16: 448000 | M16: =L16*$M$8 -> 524160 | N16: =L16*$N$8 -> 604800 | O16: =L16*$O$8 -> 703360 | P16: =L16*$P$8 -> 815360 | Q16: =L16*$Q$8 -> 949760 | R16: =L16*$R$8 -> 1075200
B17: EL TIEMPO TARDE | C17: L-V | D17: 16:00-16:15 | E17: Off | F17: 2.5461538 | G17: =L17*$G$8 -> 182400 | H17: =L17*$H$8 -> 307200 | I17: =L17*$I$8 -> 369600 | J17: =L17*$J$8 -> 417600 | K17: =L17*$K$8 -> 441600 | L17: 480000 | M17: =L17*$M$8 -> 561600 | N17: =L17*$N$8 -> 648000 | O17: =L17*$O$8 -> 753600 | P17: =L17*$P$8 -> 873600 | Q17: =L17*$Q$8 -> 1017600 | R17: =L17*$R$8 -> 1152000
B18: LA BARONESA A | C18: L-V | D18: 16:45-17:30 | E18: Off | F18: 3.2423596 | G18: =L18*$G$8 -> 323000 | H18: =L18*$H$8 -> 544000 | I18: =L18*$I$8 -> 654500 | J18: =L18*$J$8 -> 739500 | K18: =L18*$K$8 -> 782000 | L18: 850000 | M18: =L18*$M$8 -> 994500 | N18: =L18*$N$8 -> 1147500 | O18: =L18*$O$8 -> 1334500 | P18: =L18*$P$8 -> 1547000 | Q18: =L18*$Q$8 -> 1802000 | R18: =L18*$R$8 -> 2040000
B19: LA BARONESA B | C19: L-V | D19: 17:30-18:15 | E19: Off | F19: 3.8590625 | G19: =L19*$G$8 -> 361000 | H19: =L19*$H$8 -> 608000 | I19: =L19*$I$8 -> 731500 | J19: =L19*$J$8 -> 826500 | K19: =L19*$K$8 -> 874000 | L19: 950000 | M19: =L19*$M$8 -> 1111500 | N19: =L19*$N$8 -> 1282500 | O19: =L19*$O$8 -> 1491500 | P19: =L19*$P$8 -> 1729000 | Q19: =L19*$Q$8 -> 2014000 | R19: =L19*$R$8 -> 2280000
B20: MEGANOTICIAS SIEMPRE JUNTOS | C20: S-D | D20: 08:30-13:00 | E20: Off | F20: 2.0961538 | G20: =L20*$G$8 -> 124640 | H20: =L20*$H$8 -> 209920 | I20: =L20*$I$8 -> 252560 | J20: =L20*$J$8 -> 285360 | K20: =L20*$K$8 -> 301760 | L20: 328000 | M20: =L20*$M$8 -> 383760 | N20: =L20*$N$8 -> 442800 | O20: =L20*$O$8 -> 514960 | P20: =L20*$P$8 -> 596960 | Q20: =L20*$Q$8 -> 695360 | R20: =L20*$R$8 -> 787200
B21: MEGANOTICIAS ACTUALIZA FIN DE SEMANA | C21: S-D | D21: 13:00-15:00 | E21: Off | F21: 1.85 | G21: =L21*$G$8 -> 124640 | H21: =L21*$H$8 -> 209920 | I21: =L21*$I$8 -> 252560 | J21: =L21*$J$8 -> 285360 | K21: =L21*$K$8 -> 301760 | L21: 328000 | M21: =L21*$M$8 -> 383760 | N21: =L21*$N$8 -> 442800 | O21: =L21*$O$8 -> 514960 | P21: =L21*$P$8 -> 596960 | Q21: =L21*$Q$8 -> 695360 | R21: =L21*$R$8 -> 787200
B22: ACCESO A LO NUESTRO | C22: D | D22: 16:00-17:00 | E22: Off | F22: 1.423 | G22: =L22*$G$8 -> 76000 | H22: =L22*$H$8 -> 128000 | I22: =L22*$I$8 -> 154000 | J22: =L22*$J$8 -> 174000 | K22: =L22*$K$8 -> 184000 | L22: 200000 | M22: =L22*$M$8 -> 234000 | N22: =L22*$N$8 -> 270000 | O22: =L22*$O$8 -> 314000 | P22: =L22*$P$8 -> 364000 | Q22: =L22*$Q$8 -> 424000 | R22: =L22*$R$8 -> 480000
B23: A QUE COSTO | C23: S | D23: 16:00-17:00 | E23: Off | F23: 1.0185 | G23: =L23*$G$8 -> 76000 | H23: =L23*$H$8 -> 128000 | I23: =L23*$I$8 -> 154000 | J23: =L23*$J$8 -> 174000 | K23: =L23*$K$8 -> 184000 | L23: 200000 | M23: =L23*$M$8 -> 234000 | N23: =L23*$N$8 -> 270000 | O23: =L23*$O$8 -> 314000 | P23: =L23*$P$8 -> 364000 | Q23: =L23*$Q$8 -> 424000 | R23: =L23*$R$8 -> 480000
... B42: NUESTRAS FIESTAS TRASNOCHE | C42: S | D42: 00:45-01:45 | E42: Off | F42: 0.8415 | G42: =L42*$G$8 -> 39520 | H42: =L42*$H$8 -> 66560 | I42: =L42*$I$8 -> 80080 | J42: =L42*$J$8 -> 90480 | K42: =L42*$K$8 -> 95680 | L42: 104000 | M42: =L42*$M$8 -> 121680 | N42: =L42*$N$8 -> 140400 | O42: =L42*$O$8 -> 163280 | P42: =L42*$P$8 -> 189280 | Q42: =L42*$Q$8 -> 220480 | R42: =L42*$R$8 -> 249600

Sheet TVN
R2: SUPERIOR | S2: 0.77
R3: ALTA | S3: 0.77
B4: OCTUBRE 2026 | R4: MEDIA | S4: 0.8
B5: VIGENTE DESDE EL 1 AL 31 DE OCTUBRE DE 2026 | R5: BAJA | S5: 0.8
B6: PROGRAMA | C6: DIAS | D6: VIGENCIA TARIFA | E6: HORA INICIO | F6: HORA FIN | G6: ENLACE | H6: CODIGO | I6: NVL | K6: CLASIF. | L6: BLOQUE | M6: RATING | N6: Valor 5 | O6: Valor 10 | P6: Valor 15 | Q6: Valor 20 | R6: Valor 25 | S6: Valor 30 | T6: Valor 35 | U6: Valor 40 | V6: Valor 45 | W6: Valor 50 | X6: Valor 55 | Y6: Valor 60 | Z6: Valor 65
B7: AHORA CAIGO | C7: LMWJ | D7: 01 - 31 Oct. | E7: 0.79513889 | F7: 0.875 | G7: AHORA CAIGO LMWJ 01 - 31 Oct. | H7: 86025 | I7: X32 | J7: =VLOOKUP(K7,$R$2:$S$5,2,FALSE) -> 0.77 | K7: ALTA | L7: Prime time | M7: 2.48 | N7: ='[2]VALOR PREFERENCIAL (2)'!L7*(1-TVN!$J7) -> 218500 | O7: ='[2]VALOR PREFERENCIAL (2)'!M7*(1-TVN!$J7) -> 437000 | P7: ='[2]VALOR PREFERENCIAL (2)'!N7*(1-TVN!$J7) -> 500250 | Q7: ='[2]VALOR PREFERENCIAL (2)'!O7*(1-TVN!$J7) -> 598000 | R7: ='[2]VALOR PREFERENCIAL (2)'!P7*(1-TVN!$J7) -> 644000 | S7: ='[2]VALOR PREFERENCIAL (2)'!Q7*(1-TVN!$J7) -> 690000 | T7: ='[2]VALOR PREFERENCIAL (2)'!R7*(1-TVN!$J7) -> 805000 | U7: ='[2]VALOR PREFERENCIAL (2)'!S7*(1-TVN!$J7) -> 920000 | ... Z7: ='[2]VALOR PREFERENCIAL (2)'!X7*(1-TVN!$J7) -> 1719250
B8: AHORA CAIGO KIDS | C8: V | D8: 01 - 31 Oct. | E8: 0.79513889 | F8: 0.875 | G8: AHORA CAIGO KIDS V 01 - 31 Oct. | H8: 87200 | I8: X32 | J8: =VLOOKUP(K8,$R$2:$S$5,2,FALSE) -> 0.77 | K8: ALTA | L8: Prime time | M8: 2 | N8: ='[2]VALOR PREFERENCIAL (2)'!L8*(1-TVN!$J8) -> 218500 | O8: ='[2]VALOR PREFERENCIAL (2)'!M8*(1-TVN!$J8) -> 437000 | P8: ='[2]VALOR PREFERENCIAL (2)'!N8*(1-TVN!$J8) -> 500250 | Q8: ='[2]VALOR PREFERENCIAL (2)'!O8*(1-TVN!$J8) -> 598000 | R8: ='[2]VALOR PREFERENCIAL (2)'!P8*(1-TVN!$J8) -> 644000 | S8: ='[2]VALOR PREFERENCIAL (2)'!Q8*(1-TVN!$J8) -> 690000 | T8: ='[2]VALOR PREFERENCIAL (2)'!R8*(1-TVN!$J8) -> 805000 | U8: ='[2]VALOR PREFERENCIAL (2)'!S8*(1-TVN!$J8) -> 920000 | ... Z8: ='[2]VALOR PREFERENCIAL (2)'!X8*(1-TVN!$J8) -> 1719250
B9: 24 HORAS CENTRAL | C9: LMWJV | D9: 01 - 31 Oct. | E9: 0.875 | F9: 0.94791667 | G9: 24 HORAS CENTRAL LMWJV 01 - 31 Oct. | H9: 67138 | I9: X37 | J9: =VLOOKUP(K9,$R$2:$S$5,2,FALSE) -> 0.77 | K9: SUPERIOR | L9: Prime time | M9: 2.51 | N9: ='[2]VALOR PREFERENCIAL (2)'!L9*(1-TVN!$J9) -> 335110 | O9: ='[2]VALOR PREFERENCIAL (2)'!M9*(1-TVN!$J9) -> 669990 | P9: ='[2]VALOR PREFERENCIAL (2)'!N9*(1-TVN!$J9) -> 767050 | Q9: ='[2]VALOR PREFERENCIAL (2)'!O9*(1-TVN!$J9) -> 917010 | R9: ='[2]VALOR PREFERENCIAL (2)'!P9*(1-TVN!$J9) -> 987390 | S9: ='[2]VALOR PREFERENCIAL (2)'!Q9*(1-TVN!$J9) -> 1058000 | T9: ='[2]VALOR PREFERENCIAL (2)'!R9*(1-TVN!$J9) -> 1234410 | U9: ='[2]VALOR PREFERENCIAL (2)'!S9*(1-TVN!$J9) -> 1410590 | ... Z9: ='[2]VALOR PREFERENCIAL (2)'!X9*(1-TVN!$J9) -> 2636260
B10: 24 HORAS CENTRAL SABADO | C10: S | D10: 01 - 31 Oct. | E10: 0.875 | F10: 0.94097222 | G10: 24 HORAS CENTRAL SABADO S 01 - 31 Oct. | H10: 86469 | I10: X31 | J10: =VLOOKUP(K10,$R$2:$S$5,2,FALSE) -> 0.77 | K10: SUPERIOR | L10: Prime time | M10: 1.32 | N10: ='[2]VALOR PREFERENCIAL (2)'!L10*(1-TVN!$J10) -> 189290 | O10: ='[2]VALOR PREFERENCIAL (2)'!M10*(1-TVN!$J10) -> 378810 | P10: ='[2]VALOR PREFERENCIAL (2)'!N10*(1-TVN!$J10) -> 433550 | Q10: ='[2]VALOR PREFERENCIAL (2)'!O10*(1-TVN!$J10) -> 518190 | R10: ='[2]VALOR PREFERENCIAL (2)'!P10*(1-TVN!$J10) -> 558210 | S10: ='[2]VALOR PREFERENCIAL (2)'!Q10*(1-TVN!$J10) -> 598000 | T10: ='[2]VALOR PREFERENCIAL (2)'!R10*(1-TVN!$J10) -> 697590 | U10: ='[2]VALOR PREFERENCIAL (2)'!S10*(1-TVN!$J10) -> 797410 | ... Z10: ='[2]VALOR PREFERENCIAL (2)'!X10*(1-TVN!$J10) -> 1489940
B11: 24 HORAS CENTRAL DOMINGO | C11: D | D11: 01 - 31 Oct. | E11: 0.875 | F11: 0.94791667 | G11: 24 HORAS CENTRAL DOMINGO D 01 - 31 Oct. | H11: 86470 | I11: X34 | J11: =VLOOKUP(K11,$R$2:$S$5,2,FALSE) -> 0.77 | K11: SUPERIOR | L11: Prime time | M11: 2.05 | N11: ='[2]VALOR PREFERENCIAL (2)'!L11*(1-TVN!$J11) -> 254840 | O11: ='[2]VALOR PREFERENCIAL (2)'!M11*(1-TVN!$J11) -> 509910 | P11: ='[2]VALOR PREFERENCIAL (2)'!N11*(1-TVN!$J11) -> 583740 | Q11: ='[2]VALOR PREFERENCIAL (2)'!O11*(1-TVN!$J11) -> 697590 | R11: ='[2]VALOR PREFERENCIAL (2)'!P11*(1-TVN!$J11) -> 751410 | S11: ='[2]VALOR PREFERENCIAL (2)'!Q11*(1-TVN!$J11) -> 805000 | T11: ='[2]VALOR PREFERENCIAL (2)'!R11*(1-TVN!$J11) -> 939090 | U11: ='[2]VALOR PREFERENCIAL (2)'!S11*(1-TVN!$J11) -> 1073410 | ... Z11: ='[2]VALOR PREFERENCIAL (2)'!X11*(1-TVN!$J11) -> 2005830
B12: TV TIEMPO | C12: LMWJV | D12: 01 - 31 Oct. | E12: 0.94791667 | F12: 0.95138889 | G12: TV TIEMPO LMWJV 01 - 31 Oct. | H12: 10029 | I12: X37 | J12: =VLOOKUP(K12,$R$2:$S$5,2,FALSE) -> 0.77 | K12: ALTA | L12: Prime time | M12: 2.51 | N12: ='[2]VALOR PREFERENCIAL (2)'!L12*(1-TVN!$J12) -> 342240 | O12: ='[2]VALOR PREFERENCIAL (2)'!M12*(1-TVN!$J12) -> 684710 | P12: ='[2]VALOR PREFERENCIAL (2)'!N12*(1-TVN!$J12) -> 783840 | Q12: ='[2]VALOR PREFERENCIAL (2)'!O12*(1-TVN!$J12) -> 936790 | R12: ='[2]VALOR PREFERENCIAL (2)'!P12*(1-TVN!$J12) -> 1009010 | S12: ='[2]VALOR PREFERENCIAL (2)'!Q12*(1-TVN!$J12) -> 1081000 | T12: ='[2]VALOR PREFERENCIAL (2)'!R12*(1-TVN!$J12) -> 1261090 | U12: ='[2]VALOR PREFERENCIAL (2)'!S12*(1-TVN!$J12) -> 1441410 | ... Z12: ='[2]VALOR PREFERENCIAL (2)'!X12*(1-TVN!$J12) -> 2693530
B13: TV TIEMPO | C13: S | D13: 01 - 31 Oct. | E13: 0.94097222 | F13: 0.94444444 | G13: TV TIEMPO S 01 - 31 Oct. | H13: 10029 | I13: X31 | J13: =VLOOKUP(K13,$R$2:$S$5,2,FALSE) -> 0.77 | K13: ALTA | L13: Prime time | M13: 1.32 | N13: ='[2]VALOR PREFERENCIAL (2)'!L13*(1-TVN!$J13) -> 196650 | O13: ='[2]VALOR PREFERENCIAL (2)'!M13*(1-TVN!$J13) -> 393300 | P13: ='[2]VALOR PREFERENCIAL (2)'!N13*(1-TVN!$J13) -> 450340 | Q13: ='[2]VALOR PREFERENCIAL (2)'!O13*(1-TVN!$J13) -> 538200 | R13: ='[2]VALOR PREFERENCIAL (2)'!P13*(1-TVN!$J13) -> 579600 | S13: ='[2]VALOR PREFERENCIAL (2)'!Q13*(1-TVN!$J13) -> 621000 | T13: ='[2]VALOR PREFERENCIAL (2)'!R13*(1-TVN!$J13) -> 724500 | U13: ='[2]VALOR PREFERENCIAL (2)'!S13*(1-TVN!$J13) -> 828000 | ... Z13: ='[2]VALOR PREFERENCIAL (2)'!X13*(1-TVN!$J13) -> 1547440
B14: TV TIEMPO | C14: D | D14: 01 - 31 Oct. | E14: 0.94791667 | F14: 0.95138889 | G14: TV TIEMPO D 01 - 31 Oct. | H14: 10029 | I14: X34 | J14: =VLOOKUP(K14,$R$2:$S$5,2,FALSE) -> 0.77 | K14: ALTA | L14: Prime time | M14: 2.05 | N14: ='[2]VALOR PREFERENCIAL (2)'!L14*(1-TVN!$J14) -> 262200 | O14: ='[2]VALOR PREFERENCIAL (2)'!M14*(1-TVN!$J14) -> 524400 | P14: ='[2]VALOR PREFERENCIAL (2)'!N14*(1-TVN!$J14) -> 600300 | Q14: ='[2]VALOR PREFERENCIAL (2)'!O14*(1-TVN!$J14) -> 717600 | R14: ='[2]VALOR PREFERENCIAL (2)'!P14*(1-TVN!$J14) -> 772800 | S14: ='[2]VALOR PREFERENCIAL (2)'!Q14*(1-TVN!$J14) -> 828000 | T14: ='[2]VALOR PREFERENCIAL (2)'!R14*(1-TVN!$J14) -> 966000 | U14: ='[2]VALOR PREFERENCIAL (2)'!S14*(1-TVN!$J14) -> 1104000 | ... Z14: ='[2]VALOR PREFERENCIAL (2)'!X14*(1-TVN!$J14) -> 2063100
B15: MASTERCHEF CHILE | C15: LMWJD | D15: 01 - 31 Oct. | E15: 0.95138889 | F15: 0.020833333 | G15: MASTERCHEF CHILE LMWJD 01 - 31 Oct. | H15: 87364 | I15: X37 | J15: =VLOOKUP(K15,$R$2:$S$5,2,FALSE) -> 0.77 | K15: SUPERIOR | L15: Prime time | M15: 2.27 | N15: ='[2]VALOR PREFERENCIAL (2)'!L15*(1-TVN!$J15) -> 342240 | O15: ='[2]VALOR PREFERENCIAL (2)'!M15*(1-TVN!$J15) -> 684710 | P15: ='[2]VALOR PREFERENCIAL (2)'!N15*(1-TVN!$J15) -> 783840 | Q15: ='[2]VALOR PREFERENCIAL (2)'!O15*(1-TVN!$J15) -> 936790 | R15: ='[2]VALOR PREFERENCIAL (2)'!P15*(1-TVN!$J15) -> 1009010 | S15: ='[2]VALOR PREFERENCIAL (2)'!Q15*(1-TVN!$J15) -> 1081000 | T15: ='[2]VALOR PREFERENCIAL (2)'!R15*(1-TVN!$J15) -> 1261090 | U15: ='[2]VALOR PREFERENCIAL (2)'!S15*(1-TVN!$J15) -> 1441410 | ... Z15: ='[2]VALOR PREFERENCIAL (2)'!X15*(1-TVN!$J15) -> 2693530
B16: AHORA CAIGO PRIME | C16: V | D16: 01 - 31 Oct. | E16: 0.94444444 | F16: 0.03125 | G16: AHORA CAIGO PRIME V 01 - 31 Oct. | H16: 86071 | I16: X22 | J16: =VLOOKUP(K16,$R$2:$S$5,2,FALSE) -> 0.77 | K16: ALTA | L16: Prime time | M16: 0.91 | N16: ='[2]VALOR PREFERENCIAL (2)'!L16*(1-TVN!$J16) -> 83720 | O16: ='[2]VALOR PREFERENCIAL (2)'!M16*(1-TVN!$J16) -> 167440 | P16: ='[2]VALOR PREFERENCIAL (2)'!N16*(1-TVN!$J16) -> 191820 | Q16: ='[2]VALOR PREFERENCIAL (2)'!O16*(1-TVN!$J16) -> 229310 | R16: ='[2]VALOR PREFERENCIAL (2)'!P16*(1-TVN!$J16) -> 246790 | S16: ='[2]VALOR PREFERENCIAL (2)'!Q16*(1-TVN!$J16) -> 264500 | T16: ='[2]VALOR PREFERENCIAL (2)'!R16*(1-TVN!$J16) -> 308660 | U16: ='[2]VALOR PREFERENCIAL (2)'!S16*(1-TVN!$J16) -> 352590 | ... Z16: ='[2]VALOR PREFERENCIAL (2)'!X16*(1-TVN!$J16) -> 658950
B17: BEST SELLER | C17: S | D17: 01 - 31 Oct. | E17: 0.94444444 | F17: 0.03125 | G17: BEST SELLER S 01 - 31 Oct. | H17: 82858 | I17: X23 | J17: =VLOOKUP(K17,$R$2:$S$5,2,FALSE) -> 0.77 | K17: ALTA | L17: Prime time | M17: 0.76 | N17: ='[2]VALOR PREFERENCIAL (2)'!L17*(1-TVN!$J17) -> 87400 | O17: ='[2]VALOR PREFERENCIAL (2)'!M17*(1-TVN!$J17) -> 174800 | P17: ='[2]VALOR PREFERENCIAL (2)'!N17*(1-TVN!$J17) -> 200100 | Q17: ='[2]VALOR PREFERENCIAL (2)'!O17*(1-TVN!$J17) -> 239200 | R17: ='[2]VALOR PREFERENCIAL (2)'!P17*(1-TVN!$J17) -> 257600 | S17: ='[2]VALOR PREFERENCIAL (2)'!Q17*(1-TVN!$J17) -> 276000 | T17: ='[2]VALOR PREFERENCIAL (2)'!R17*(1-TVN!$J17) -> 322000 | U17: ='[2]VALOR PREFERENCIAL (2)'!S17*(1-TVN!$J17) -> 368000 | ... Z17: ='[2]VALOR PREFERENCIAL (2)'!X17*(1-TVN!$J17) -> 687700
B18: AVENIDA BRASIL | C18: LMWJD | D18: 01 - 31 Oct. | E18: 0.020833333 | F18: 0.0625 | G18: AVENIDA BRASIL LMWJD 01 - 31 Oct. | H18: 87129 | I18: X9 | J18: =VLOOKUP(K18,$R$2:$S$5,2,FALSE) -> 0.8 | K18: MEDIA | L18: Off | M18: 0.83 | N18: ='[2]VALOR PREFERENCIAL (2)'!L18*(1-TVN!$J18) -> 20600 | O18: ='[2]VALOR PREFERENCIAL (2)'!M18*(1-TVN!$J18) -> 41200 | P18: ='[2]VALOR PREFERENCIAL (2)'!N18*(1-TVN!$J18) -> 47200 | Q18: ='[2]VALOR PREFERENCIAL (2)'!O18*(1-TVN!$J18) -> 56400 | R18: ='[2]VALOR PREFERENCIAL (2)'!P18*(1-TVN!$J18) -> 60600 | S18: ='[2]VALOR PREFERENCIAL (2)'!Q18*(1-TVN!$J18) -> 65000 | T18: ='[2]VALOR PREFERENCIAL (2)'!R18*(1-TVN!$J18) -> 75800 | U18: ='[2]VALOR PREFERENCIAL (2)'!S18*(1-TVN!$J18) -> 86600 | ... Z18: ='[2]VALOR PREFERENCIAL (2)'!X18*(1-TVN!$J18) -> 162000
B19: 24 HORAS AL CIERRE | C19: LMWJ | D19: 01 - 31 Oct. | E19: 0.0625 | F19: 0.09375 | G19: 24 HORAS AL CIERRE LMWJ 01 - 31 Oct. | H19: 86272 | I19: X6 | J19: =VLOOKUP(K19,$R$2:$S$5,2,FALSE) -> 0.8 | K19: MEDIA | L19: Off | M19: 0.63 | N19: ='[2]VALOR PREFERENCIAL (2)'!L19*(1-TVN!$J19) -> 15800 | O19: ='[2]VALOR PREFERENCIAL (2)'!M19*(1-TVN!$J19) -> 31600 | P19: ='[2]VALOR PREFERENCIAL (2)'!N19*(1-TVN!$J19) -> 36200 | Q19: ='[2]VALOR PREFERENCIAL (2)'!O19*(1-TVN!$J19) -> 43400 | R19: ='[2]VALOR PREFERENCIAL (2)'!P19*(1-TVN!$J19) -> 46600 | S19: ='[2]VALOR PREFERENCIAL (2)'!Q19*(1-TVN!$J19) -> 50000 | T19: ='[2]VALOR PREFERENCIAL (2)'!R19*(1-TVN!$J19) -> 58400 | U19: ='[2]VALOR PREFERENCIAL (2)'!S19*(1-TVN!$J19) -> 66600 | ... Z19: ='[2]VALOR PREFERENCIAL (2)'!X19*(1-TVN!$J19) -> 124600
B20: 24 HORAS TU MAÑANA (A) | C20: LMWJV | D20: 01 - 31 Oct. | E20: 0.25 | F20: 0.29166667 | G20: 24 HORAS TU MAÑANA (A) LMWJV 01 - 31 Oct. | H20: 86273 | I20: X8 | J20: =VLOOKUP(K20,$R$2:$S$5,2,FALSE) -> 0.8 | K20: MEDIA | L20: Off | M20: 0.41 | N20: ='[2]VALOR PREFERENCIAL (2)'!L33*(1-TVN!$J20) -> 19000 | O20: ='[2]VALOR PREFERENCIAL (2)'!M33*(1-TVN!$J20) -> 38000 | P20: ='[2]VALOR PREFERENCIAL (2)'!N33*(1-TVN!$J20) -> 43600 | Q20: ='[2]VALOR PREFERENCIAL (2)'!O33*(1-TVN!$J20) -> 52000 | R20: ='[2]VALOR PREFERENCIAL (2)'!P33*(1-TVN!$J20) -> 56000 | S20: ='[2]VALOR PREFERENCIAL (2)'!Q33*(1-TVN!$J20) -> 60000 | T20: ='[2]VALOR PREFERENCIAL (2)'!R33*(1-TVN!$J20) -> 70000 | U20: ='[2]VALOR PREFERENCIAL (2)'!S33*(1-TVN!$J20) -> 80000 | ... Z20: ='[2]VALOR PREFERENCIAL (2)'!X33*(1-TVN!$J20) -> 149600
B21: 24 HORAS TU MAÑANA (B) | C21: LMWJV | D21: 01 - 31 Oct. | E21: 0.29166667 | F21: 0.33333333 | G21: 24 HORAS TU MAÑANA (B) LMWJV 01 - 31 Oct. | H21: 86274 | I21: X15 | J21: =VLOOKUP(K21,$R$2:$S$5,2,FALSE) -> 0.8 | K21: MEDIA | L21: Off | M21: 0.7 | N21: ='[2]VALOR PREFERENCIAL (2)'!L34*(1-TVN!$J21) -> 38000 | O21: ='[2]VALOR PREFERENCIAL (2)'!M34*(1-TVN!$J21) -> 76000 | P21: ='[2]VALOR PREFERENCIAL (2)'!N34*(1-TVN!$J21) -> 87000 | Q21: ='[2]VALOR PREFERENCIAL (2)'!O34*(1-TVN!$J21) -> 104000 | R21: ='[2]VALOR PREFERENCIAL (2)'!P34*(1-TVN!$J21) -> 112000 | S21: ='[2]VALOR PREFERENCIAL (2)'!Q34*(1-TVN!$J21) -> 120000 | T21: ='[2]VALOR PREFERENCIAL (2)'!R34*(1-TVN!$J21) -> 140000 | U21: ='[2]VALOR PREFERENCIAL (2)'!S34*(1-TVN!$J21) -> 160000 | ... Z21: ='[2]VALOR PREFERENCIAL (2)'!X34*(1-TVN!$J21) -> 299000
B22: BUENOS DIAS A TODOS | C22: LMWJV | D22: 01 - 31 Oct. | E22: 0.33333333 | F22: 0.45833333 | G22: BUENOS DIAS A TODOS LMWJV 01 - 31 Oct. | H22: 10463 | I22: X17 | J22: =VLOOKUP(K22,$R$2:$S$5,2,FALSE) -> 0.8 | K22: MEDIA | L22: Off | M22: 0.98 | N22: ='[2]VALOR PREFERENCIAL (2)'!L35*(1-TVN!$J22) -> 44400 | O22: ='[2]VALOR PREFERENCIAL (2)'!M35*(1-TVN!$J22) -> 88600 | P22: ='[2]VALOR PREFERENCIAL (2)'!N35*(1-TVN!$J22) -> 101600 | Q22: ='[2]VALOR PREFERENCIAL (2)'!O35*(1-TVN!$J22) -> 121400 | R22: ='[2]VALOR PREFERENCIAL (2)'!P35*(1-TVN!$J22) -> 130600 | S22: ='[2]VALOR PREFERENCIAL (2)'!Q35*(1-TVN!$J22) -> 140000 | T22: ='[2]VALOR PREFERENCIAL (2)'!R35*(1-TVN!$J22) -> 163400 | U22: ='[2]VALOR PREFERENCIAL (2)'!S35*(1-TVN!$J22) -> 186600 | ... Z22: ='[2]VALOR PREFERENCIAL (2)'!X35*(1-TVN!$J22) -> 348800
B23: EL MEDIO DIA | C23: LMWJV | D23: 01 - 31 Oct. | E23: 0.45833333 | F23: 0.54166667 | G23: EL MEDIO DIA LMWJV 01 - 31 Oct. | H23: 86555 | I23: X18 | J23: =VLOOKUP(K23,$R$2:$S$5,2,FALSE) -> 0.8 | K23: MEDIA | L23: Off | M23: 1.11 | N23: ='[2]VALOR PREFERENCIAL (2)'!L36*(1-TVN!$J23) -> 50600 | O23: ='[2]VALOR PREFERENCIAL (2)'!M36*(1-TVN!$J23) -> 101400 | P23: ='[2]VALOR PREFERENCIAL (2)'!N36*(1-TVN!$J23) -> 116000 | Q23: ='[2]VALOR PREFERENCIAL (2)'!O36*(1-TVN!$J23) -> 138600 | R23: ='[2]VALOR PREFERENCIAL (2)'!P36*(1-TVN!$J23) -> 149400 | S23: ='[2]VALOR PREFERENCIAL (2)'!Q36*(1-TVN!$J23) -> 160000 | T23: ='[2]VALOR PREFERENCIAL (2)'!R36*(1-TVN!$J23) -> 186600 | U23: ='[2]VALOR PREFERENCIAL (2)'!S36*(1-TVN!$J23) -> 213400 | ... Z23: ='[2]VALOR PREFERENCIAL (2)'!X36*(1-TVN!$J23) -> 398600
B24: 24 HORAS AL DIA | C24: LMWJV | D24: 01 - 31 Oct. | E24: 0.54166667 | F24: 0.625 | G24: 24 HORAS AL DIA LMWJV 01 - 31 Oct. | H24: 67141 | I24: X21 | J24: =VLOOKUP(K24,$R$2:$S$5,2,FALSE) -> 0.8 | K24: MEDIA | L24: Off | M24: 1.25 | N24: ='[2]VALOR PREFERENCIAL (2)'!L37*(1-TVN!$J24) -> 63400 | O24: ='[2]VALOR PREFERENCIAL (2)'!M37*(1-TVN!$J24) -> 126600 | P24: ='[2]VALOR PREFERENCIAL (2)'!N37*(1-TVN!$J24) -> 145000 | Q24: ='[2]VALOR PREFERENCIAL (2)'!O37*(1-TVN!$J24) -> 173400 | R24: ='[2]VALOR PREFERENCIAL (2)'!P37*(1-TVN!$J24) -> 186600 | S24: ='[2]VALOR PREFERENCIAL (2)'!Q37*(1-TVN!$J24) -> 200000 | T24: ='[2]VALOR PREFERENCIAL (2)'!R37*(1-TVN!$J24) -> 233400 | U24: ='[2]VALOR PREFERENCIAL (2)'!S37*(1-TVN!$J24) -> 266600 | ... Z24: ='[2]VALOR PREFERENCIAL (2)'!X37*(1-TVN!$J24) -> 498400
B25: PAMPA ILUSION | C25: LMWJV | D25: 01 - 31 Oct. | E25: 0.625 | F25: 0.67708333 | G25: PAMPA ILUSION LMWJV 01 - 31 Oct. | H25: 72207 | I25: X27 | J25: =VLOOKUP(K25,$R$2:$S$5,2,FALSE) -> 0.8 | K25: MEDIA | L25: Off | M25: 2.3 | N25: ='[2]VALOR PREFERENCIAL (2)'!L38*(1-TVN!$J25) -> 117200 | O25: ='[2]VALOR PREFERENCIAL (2)'!M38*(1-TVN!$J25) -> 234400 | P25: ='[2]VALOR PREFERENCIAL (2)'!N38*(1-TVN!$J25) -> 268200 | Q25: ='[2]VALOR PREFERENCIAL (2)'!O38*(1-TVN!$J25) -> 320600 | R25: ='[2]VALOR PREFERENCIAL (2)'!P38*(1-TVN!$J25) -> 345400 | S25: ='[2]VALOR PREFERENCIAL (2)'!Q38*(1-TVN!$J25) -> 370000 | T25: ='[2]VALOR PREFERENCIAL (2)'!R38*(1-TVN!$J25) -> 431600 | U25: ='[2]VALOR PREFERENCIAL (2)'!S38*(1-TVN!$J25) -> 493400 | ... Z25: ='[2]VALOR PREFERENCIAL (2)'!X38*(1-TVN!$J25) -> 922000
B26: LA PROMESA | C26: LMWJV | D26: 01 - 31 Oct. | E26: 0.67708333 | F26: 0.71875 | G26: LA PROMESA LMWJV 01 - 31 Oct. | H26: 86994 | I26: X21 | J26: =VLOOKUP(K26,$R$2:$S$5,2,FALSE) -> 0.8 | K26: MEDIA | L26: Off | M26: 1.37 | N26: ='[2]VALOR PREFERENCIAL (2)'!L39*(1-TVN!$J26) -> 63400 | O26: ='[2]VALOR PREFERENCIAL (2)'!M39*(1-TVN!$J26) -> 126600 | P26: ='[2]VALOR PREFERENCIAL (2)'!N39*(1-TVN!$J26) -> 145000 | Q26: ='[2]VALOR PREFERENCIAL (2)'!O39*(1-TVN!$J26) -> 173400 | R26: ='[2]VALOR PREFERENCIAL (2)'!P39*(1-TVN!$J26) -> 186600 | S26: ='[2]VALOR PREFERENCIAL (2)'!Q39*(1-TVN!$J26) -> 200000 | T26: ='[2]VALOR PREFERENCIAL (2)'!R39*(1-TVN!$J26) -> 233400 | U26: ='[2]VALOR PREFERENCIAL (2)'!S39*(1-TVN!$J26) -> 266600 | ... Z26: ='[2]VALOR PREFERENCIAL (2)'!X39*(1-TVN!$J26) -> 498400
B27: CASO CERRADO | C27: LMWJV | D27: 01 - 31 Oct. | E27: 0.71875 | F27: 0.79513889 | G27: CASO CERRADO LMWJV 01 - 31 Oct. | H27: 85956 | I27: X23 | J27: =VLOOKUP(K27,$R$2:$S$5,2,FALSE) -> 0.8 | K27: MEDIA | L27: Off | M27: 1.54 | N27: ='[2]VALOR PREFERENCIAL (2)'!L40*(1-TVN!$J27) -> 76000 | O27: ='[2]VALOR PREFERENCIAL (2)'!M40*(1-TVN!$J27) -> 152000 | P27: ='[2]VALOR PREFERENCIAL (2)'!N40*(1-TVN!$J27) -> 174000 | Q27: ='[2]VALOR PREFERENCIAL (2)'!O40*(1-TVN!$J27) -> 208000 | R27: ='[2]VALOR PREFERENCIAL (2)'!P40*(1-TVN!$J27) -> 224000 | S27: ='[2]VALOR PREFERENCIAL (2)'!Q40*(1-TVN!$J27) -> 240000 | T27: ='[2]VALOR PREFERENCIAL (2)'!R40*(1-TVN!$J27) -> 280000 | U27: ='[2]VALOR PREFERENCIAL (2)'!S40*(1-TVN!$J27) -> 320000 | ... Z27: ='[2]VALOR PREFERENCIAL (2)'!X40*(1-TVN!$J27) -> 598000
B28: EL CHAPULIN COLORADO | C28: S | D28: 01 - 31 Oct. | E28: 0.30208333 | F28: 0.35416667 | G28: EL CHAPULIN COLORADO S 01 - 31 Oct. | H28: 86484 | I28: X2 | J28: =VLOOKUP(K28,$R$2:$S$5,2,FALSE) -> 0.8 | K28: BAJA | L28: Off | M28: 0.25 | N28: ='[2]VALOR PREFERENCIAL (2)'!L42*(1-TVN!$J28) -> 9600 | O28: ='[2]VALOR PREFERENCIAL (2)'!M42*(1-TVN!$J28) -> 19000 | P28: ='[2]VALOR PREFERENCIAL (2)'!N42*(1-TVN!$J28) -> 21800 | Q28: ='[2]VALOR PREFERENCIAL (2)'!O42*(1-TVN!$J28) -> 26000 | R28: ='[2]VALOR PREFERENCIAL (2)'!P42*(1-TVN!$J28) -> 28000 | S28: ='[2]VALOR PREFERENCIAL (2)'!Q42*(1-TVN!$J28) -> 30000 | T28: ='[2]VALOR PREFERENCIAL (2)'!R42*(1-TVN!$J28) -> 35000 | U28: ='[2]VALOR PREFERENCIAL (2)'!S42*(1-TVN!$J28) -> 40000 | ... Z28: ='[2]VALOR PREFERENCIAL (2)'!X42*(1-TVN!$J28) -> 74800
B29: CHILENOS DE NORTE A SUR | C29: S | D29: 01 - 31 Oct. | E29: 0.35416667 | F29: 0.4375 | G29: CHILENOS DE NORTE A SUR S 01 - 31 Oct. | H29: 86995 | I29: X4 | J29: =VLOOKUP(K29,$R$2:$S$5,2,FALSE) -> 0.8 | K29: BAJA | L29: Off | M29: 0.41 | N29: ='[2]VALOR PREFERENCIAL (2)'!L43*(1-TVN!$J29) -> 12600 | O29: ='[2]VALOR PREFERENCIAL (2)'!M43*(1-TVN!$J29) -> 25400 | P29: ='[2]VALOR PREFERENCIAL (2)'!N43*(1-TVN!$J29) -> 29000 | Q29: ='[2]VALOR PREFERENCIAL (2)'!O43*(1-TVN!$J29) -> 34600 | R29: ='[2]VALOR PREFERENCIAL (2)'!P43*(1-TVN!$J29) -> 37400 | S29: ='[2]VALOR PREFERENCIAL (2)'!Q43*(1-TVN!$J29) -> 40000 | T29: ='[2]VALOR PREFERENCIAL (2)'!R43*(1-TVN!$J29) -> 46600 | U29: ='[2]VALOR PREFERENCIAL (2)'!S43*(1-TVN!$J29) -> 53400 | ... Z29: ='[2]VALOR PREFERENCIAL (2)'!X43*(1-TVN!$J29) -> 99600
B30: EL CHAVO DEL OCHO SABADO | C30: S | D30: 01 - 31 Oct. | E30: 0.4375 | F30: 0.5625 | G30: EL CHAVO DEL OCHO SABADO S 01 - 31 Oct. | H30: 86647 | I30: X14 | J30: =VLOOKUP(K30,$R$2:$S$5,2,FALSE) -> 0.8 | K30: MEDIA | L30: Off | M30: 0.91 | N30: ='[2]VALOR PREFERENCIAL (2)'!L44*(1-TVN!$J30) -> 31600 | O30: ='[2]VALOR PREFERENCIAL (2)'!M44*(1-TVN!$J30) -> 63400 | P30: ='[2]VALOR PREFERENCIAL (2)'!N44*(1-TVN!$J30) -> 72600 | Q30: ='[2]VALOR PREFERENCIAL (2)'!O44*(1-TVN!$J30) -> 86600 | R30: ='[2]VALOR PREFERENCIAL (2)'!P44*(1-TVN!$J30) -> 93400 | S30: ='[2]VALOR PREFERENCIAL (2)'!Q44*(1-TVN!$J30) -> 100000 | T30: ='[2]VALOR PREFERENCIAL (2)'!R44*(1-TVN!$J30) -> 116600 | U30: ='[2]VALOR PREFERENCIAL (2)'!S44*(1-TVN!$J30) -> 133400 | ... Z30: ='[2]VALOR PREFERENCIAL (2)'!X44*(1-TVN!$J30) -> 249200
B31: 24 HORAS AL DIA | C31: S | D31: 01 - 31 Oct. | E31: 0.5625 | F31: 0.64583333 | G31: 24 HORAS AL DIA S 01 - 31 Oct. | H31: 67141 | I31: X18 | J31: =VLOOKUP(K31,$R$2:$S$5,2,FALSE) -> 0.8 | K31: MEDIA | L31: Off | M31: 0.9 | N31: ='[2]VALOR PREFERENCIAL (2)'!L45*(1-TVN!$J31) -> 50600 | O31: ='[2]VALOR PREFERENCIAL (2)'!M45*(1-TVN!$J31) -> 101400 | P31: ='[2]VALOR PREFERENCIAL (2)'!N45*(1-TVN!$J31) -> 116000 | Q31: ='[2]VALOR PREFERENCIAL (2)'!O45*(1-TVN!$J31) -> 138600 | R31: ='[2]VALOR PREFERENCIAL (2)'!P45*(1-TVN!$J31) -> 149400 | S31: ='[2]VALOR PREFERENCIAL (2)'!Q45*(1-TVN!$J31) -> 160000 | T31: ='[2]VALOR PREFERENCIAL (2)'!R45*(1-TVN!$J31) -> 186600 | U31: ='[2]VALOR PREFERENCIAL (2)'!S45*(1-TVN!$J31) -> 213400 | ... Z31: ='[2]VALOR PREFERENCIAL (2)'!X45*(1-TVN!$J31) -> 398600
B32: SUPER CINE PM (A) | C32: S | D32: 01 - 31 Oct. | E32: 0.64583333 | F32: 0.71875 | G32: SUPER CINE PM (A) S 01 - 31 Oct. | H32: 85340 | I32: X18 | J32: =VLOOKUP(K32,$R$2:$S$5,2,FALSE) -> 0.8 | K32: MEDIA | L32: Off | M32: 1.1 | N32: ='[2]VALOR PREFERENCIAL (2)'!L46*(1-TVN!$J32) -> 47600 | O32: ='[2]VALOR PREFERENCIAL (2)'!M46*(1-TVN!$J32) -> 95000 | P32: ='[2]VALOR PREFERENCIAL (2)'!N46*(1-TVN!$J32) -> 108800 | Q32: ='[2]VALOR PREFERENCIAL (2)'!O46*(1-TVN!$J32) -> 130000 | R32: ='[2]VALOR PREFERENCIAL (2)'!P46*(1-TVN!$J32) -> 140000 | S32: ='[2]VALOR PREFERENCIAL (2)'!Q46*(1-TVN!$J32) -> 150000 | T32: ='[2]VALOR PREFERENCIAL (2)'!R46*(1-TVN!$J32) -> 175000 | U32: ='[2]VALOR PREFERENCIAL (2)'!S46*(1-TVN!$J32) -> 200000 | ... Z32: ='[2]VALOR PREFERENCIAL (2)'!X46*(1-TVN!$J32) -> 373800
B33: SUPER CINE PM (B) | C33: S | D33: 01 - 31 Oct. | E33: 0.71875 | F33: 0.79166667 | G33: SUPER CINE PM (B) S 01 - 31 Oct. | H33: 85341 | I33: X19 | J33: =VLOOKUP(K33,$R$2:$S$5,2,FALSE) -> 0.8 | K33: MEDIA | L33: Off | M33: 1.01 | N33: ='[2]VALOR PREFERENCIAL (2)'!L47*(1-TVN!$J33) -> 53800 | O33: ='[2]VALOR PREFERENCIAL (2)'!M47*(1-TVN!$J33) -> 107600 | P33: ='[2]VALOR PREFERENCIAL (2)'!N47*(1-TVN!$J33) -> 123200 | Q33: ='[2]VALOR PREFERENCIAL (2)'!O47*(1-TVN!$J33) -> 147400 | R33: ='[2]VALOR PREFERENCIAL (2)'!P47*(1-TVN!$J33) -> 158600 | S33: ='[2]VALOR PREFERENCIAL (2)'!Q47*(1-TVN!$J33) -> 170000 | T33: ='[2]VALOR PREFERENCIAL (2)'!R47*(1-TVN!$J33) -> 198400 | U33: ='[2]VALOR PREFERENCIAL (2)'!S47*(1-TVN!$J33) -> 226600 | ... Z33: ='[2]VALOR PREFERENCIAL (2)'!X47*(1-TVN!$J33) -> 423600
B34: MASTERCHEF (LO MEJOR) SAB | C34: S | D34: 01 - 31 Oct. | E34: 0.79166667 | F34: 0.875 | G34: MASTERCHEF (LO MEJOR) SAB S 01 - 31 Oct. | H34: 87360 | I34: X24 | J34: =VLOOKUP(K34,$R$2:$S$5,2,FALSE) -> 0.8 | K34: MEDIA | L34: Off | M34: 1.73 | N34: ='[2]VALOR PREFERENCIAL (2)'!L48*(1-TVN!$J34) -> 82400 | O34: ='[2]VALOR PREFERENCIAL (2)'!M48*(1-TVN!$J34) -> 164600 | P34: ='[2]VALOR PREFERENCIAL (2)'!N48*(1-TVN!$J34) -> 188600 | Q34: ='[2]VALOR PREFERENCIAL (2)'!O48*(1-TVN!$J34) -> 225400 | R34: ='[2]VALOR PREFERENCIAL (2)'!P48*(1-TVN!$J34) -> 242600 | S34: ='[2]VALOR PREFERENCIAL (2)'!Q48*(1-TVN!$J34) -> 260000 | T34: ='[2]VALOR PREFERENCIAL (2)'!R48*(1-TVN!$J34) -> 303400 | U34: ='[2]VALOR PREFERENCIAL (2)'!S48*(1-TVN!$J34) -> 346600 | ... Z34: ='[2]VALOR PREFERENCIAL (2)'!X48*(1-TVN!$J34) -> 647800
B35: EL CHAPULIN COLORADO | C35: D | D35: 01 - 31 Oct. | E35: 0.30208333 | F35: 0.33333333 | G35: EL CHAPULIN COLORADO D 01 - 31 Oct. | H35: 86484 | I35: X2 | J35: =VLOOKUP(K35,$R$2:$S$5,2,FALSE) -> 0.8 | K35: BAJA | L35: Off | M35: 0.25 | N35: ='[2]VALOR PREFERENCIAL (2)'!L50*(1-TVN!$J35) -> 9600 | O35: ='[2]VALOR PREFERENCIAL (2)'!M50*(1-TVN!$J35) -> 19000 | P35: ='[2]VALOR PREFERENCIAL (2)'!N50*(1-TVN!$J35) -> 21800 | Q35: ='[2]VALOR PREFERENCIAL (2)'!O50*(1-TVN!$J35) -> 26000 | R35: ='[2]VALOR PREFERENCIAL (2)'!P50*(1-TVN!$J35) -> 28000 | S35: ='[2]VALOR PREFERENCIAL (2)'!Q50*(1-TVN!$J35) -> 30000 | T35: ='[2]VALOR PREFERENCIAL (2)'!R50*(1-TVN!$J35) -> 35000 | U35: ='[2]VALOR PREFERENCIAL (2)'!S50*(1-TVN!$J35) -> 40000 | ... Z35: ='[2]VALOR PREFERENCIAL (2)'!X50*(1-TVN!$J35) -> 74800
B36: 24 HORAS A LA HORA DOMINGO | C36: D | D36: 01 - 31 Oct. | E36: 0.375 | F36: 0.39583333 | G36: 24 HORAS A LA HORA DOMINGO D 01 - 31 Oct. | H36: 87085 | I36: X6 | J36: =VLOOKUP(K36,$R$2:$S$5,2,FALSE) -> 0.8 | K36: BAJA | L36: Off | M36: 0.82 | N36: ='[2]VALOR PREFERENCIAL (2)'!L52*(1-TVN!$J36) -> 15800 | O36: ='[2]VALOR PREFERENCIAL (2)'!M52*(1-TVN!$J36) -> 31600 | P36: ='[2]VALOR PREFERENCIAL (2)'!N52*(1-TVN!$J36) -> 36200 | Q36: ='[2]VALOR PREFERENCIAL (2)'!O52*(1-TVN!$J36) -> 43400 | R36: ='[2]VALOR PREFERENCIAL (2)'!P52*(1-TVN!$J36) -> 46600 | S36: ='[2]VALOR PREFERENCIAL (2)'!Q52*(1-TVN!$J36) -> 50000 | T36: ='[2]VALOR PREFERENCIAL (2)'!R52*(1-TVN!$J36) -> 58400 | U36: ='[2]VALOR PREFERENCIAL (2)'!S52*(1-TVN!$J36) -> 66600 | ... Z36: ='[2]VALOR PREFERENCIAL (2)'!X52*(1-TVN!$J36) -> 124600
B37: ESTADO NACIONAL | C37: D | D37: 01 - 31 Oct. | E37: 0.39583333 | F37: 0.46875 | G37: ESTADO NACIONAL D 01 - 31 Oct. | H37: 69474 | I37: X11 | J37: =VLOOKUP(K37,$R$2:$S$5,2,FALSE) -> 0.8 | K37: MEDIA | L37: Off | M37: 0.56 | N37: ='[2]VALOR PREFERENCIAL (2)'!L53*(1-TVN!$J37) -> 25400 | O37: ='[2]VALOR PREFERENCIAL (2)'!M53*(1-TVN!$J37) -> 50600 | P37: ='[2]VALOR PREFERENCIAL (2)'!N53*(1-TVN!$J37) -> 58000 | Q37: ='[2]VALOR PREFERENCIAL (2)'!O53*(1-TVN!$J37) -> 69400 | R37: ='[2]VALOR PREFERENCIAL (2)'!P53*(1-TVN!$J37) -> 74600 | S37: ='[2]VALOR PREFERENCIAL (2)'!Q53*(1-TVN!$J37) -> 80000 | T37: ='[2]VALOR PREFERENCIAL (2)'!R53*(1-TVN!$J37) -> 93400 | U37: ='[2]VALOR PREFERENCIAL (2)'!S53*(1-TVN!$J37) -> 106600 | ... Z37: ='[2]VALOR PREFERENCIAL (2)'!X53*(1-TVN!$J37) -> 199400
B38: CANTINFLAS EN TVN | C38: D | D38: 01 - 31 Oct. | E38: 0.46875 | F38: 0.5625 | G38: CANTINFLAS EN TVN D 01 - 31 Oct. | H38: 85139 | I38: X15 | J38: =VLOOKUP(K38,$R$2:$S$5,2,FALSE) -> 0.8 | K38: MEDIA | L38: Off | M38: 0.83 | N38: ='[2]VALOR PREFERENCIAL (2)'!L54*(1-TVN!$J38) -> 34800 | O38: ='[2]VALOR PREFERENCIAL (2)'!M54*(1-TVN!$J38) -> 69600 | P38: ='[2]VALOR PREFERENCIAL (2)'!N54*(1-TVN!$J38) -> 79800 | Q38: ='[2]VALOR PREFERENCIAL (2)'!O54*(1-TVN!$J38) -> 95400 | R38: ='[2]VALOR PREFERENCIAL (2)'!P54*(1-TVN!$J38) -> 102600 | S38: ='[2]VALOR PREFERENCIAL (2)'!Q54*(1-TVN!$J38) -> 110000 | T38: ='[2]VALOR PREFERENCIAL (2)'!R54*(1-TVN!$J38) -> 128400 | U38: ='[2]VALOR PREFERENCIAL (2)'!S54*(1-TVN!$J38) -> 146600 | ... Z38: ='[2]VALOR PREFERENCIAL (2)'!X54*(1-TVN!$J38) -> 274000
B39: 24 HORAS AL DIA | C39: D | D39: 01 - 31 Oct. | E39: 0.5625 | F39: 0.64583333 | G39: 24 HORAS AL DIA D 01 - 31 Oct. | H39: 67141 | I39: X17 | J39: =VLOOKUP(K39,$R$2:$S$5,2,FALSE) -> 0.8 | K39: MEDIA | L39: Off | M39: 1.1 | N39: ='[2]VALOR PREFERENCIAL (2)'!L55*(1-TVN!$J39) -> 44400 | O39: ='[2]VALOR PREFERENCIAL (2)'!M55*(1-TVN!$J39) -> 88600 | P39: ='[2]VALOR PREFERENCIAL (2)'!N55*(1-TVN!$J39) -> 101600 | Q39: ='[2]VALOR PREFERENCIAL (2)'!O55*(1-TVN!$J39) -> 121400 | R39: ='[2]VALOR PREFERENCIAL (2)'!P55*(1-TVN!$J39) -> 130600 | S39: ='[2]VALOR PREFERENCIAL (2)'!Q55*(1-TVN!$J39) -> 140000 | T39: ='[2]VALOR PREFERENCIAL (2)'!R55*(1-TVN!$J39) -> 163400 | U39: ='[2]VALOR PREFERENCIAL (2)'!S55*(1-TVN!$J39) -> 186600 | ... Z39: ='[2]VALOR PREFERENCIAL (2)'!X55*(1-TVN!$J39) -> 348800
B40: CHILE CONECTADO (A) | C40: D | D40: 01 - 31 Oct. | E40: 0.64583333 | F40: 0.73958333 | G40: CHILE CONECTADO (A) D 01 - 31 Oct. | H40: 87082 | I40: X15 | J40: =VLOOKUP(K40,$R$2:$S$5,2,FALSE) -> 0.8 | K40: MEDIA | L40: Off | M40: 0.76 | N40: ='[2]VALOR PREFERENCIAL (2)'!L56*(1-TVN!$J40) -> 34800 | O40: ='[2]VALOR PREFERENCIAL (2)'!M56*(1-TVN!$J40) -> 69600 | P40: ='[2]VALOR PREFERENCIAL (2)'!N56*(1-TVN!$J40) -> 79800 | Q40: ='[2]VALOR PREFERENCIAL (2)'!O56*(1-TVN!$J40) -> 95400 | R40: ='[2]VALOR PREFERENCIAL (2)'!P56*(1-TVN!$J40) -> 102600 | S40: ='[2]VALOR PREFERENCIAL (2)'!Q56*(1-TVN!$J40) -> 110000 | T40: ='[2]VALOR PREFERENCIAL (2)'!R56*(1-TVN!$J40) -> 128400 | U40: ='[2]VALOR PREFERENCIAL (2)'!S56*(1-TVN!$J40) -> 146600 | ... Z40: ='[2]VALOR PREFERENCIAL (2)'!X56*(1-TVN!$J40) -> 274000
B41: CHILE CONECTADO (B) | C41: D | D41: 01 - 31 Oct. | E41: 0.73958333 | F41: 0.83333333 | G41: CHILE CONECTADO (B) D 01 - 31 Oct. | H41: 87083 | I41: X16 | J41: =VLOOKUP(K41,$R$2:$S$5,2,FALSE) -> 0.8 | K41: MEDIA | L41: Off | M41: 0.52 | N41: ='[2]VALOR PREFERENCIAL (2)'!L57*(1-TVN!$J41) -> 41200 | O41: ='[2]VALOR PREFERENCIAL (2)'!M57*(1-TVN!$J41) -> 82400 | P41: ='[2]VALOR PREFERENCIAL (2)'!N57*(1-TVN!$J41) -> 94200 | Q41: ='[2]VALOR PREFERENCIAL (2)'!O57*(1-TVN!$J41) -> 112600 | R41: ='[2]VALOR PREFERENCIAL (2)'!P57*(1-TVN!$J41) -> 121400 | S41: ='[2]VALOR PREFERENCIAL (2)'!Q57*(1-TVN!$J41) -> 130000 | T41: ='[2]VALOR PREFERENCIAL (2)'!R57*(1-TVN!$J41) -> 151600 | U41: ='[2]VALOR PREFERENCIAL (2)'!S57*(1-TVN!$J41) -> 173400 | ... Z41: ='[2]VALOR PREFERENCIAL (2)'!X57*(1-TVN!$J41) -> 324000
...

Sheet Canal 13
B2: PROGRAMAS L-V | C2: DIAS | D2: BLOQUE | E2: RATING | F2: Valor 5 | G2: Valor 10 | H2: Valor 15 | I2: Valor 20 | J2: Valor 25 | K2: Valor 30 | L2: Valor 35 | M2: Valor 40 | N2: Valor 45 | O2: Valor 50 | P2: Valor 55 | Q2: Valor 60 | R2: Valor 65 | S2: Valor 70
B3: TRES POR TRES | C3: L-V | D3: Off | E3: 0.33 | F3: 22000 | G3: 40000 | H3: 45750 | I3: 54500 | J3: 58250 | K3: 62500 | L3: 73250 | M3: 83750 | N3: 93750 | O3: 120000 | P3: 132000 | Q3: 143750 | R3: 159500 | S3: 182500
B4: TELETRECE A.M. | C4: L-V | D4: Off | E4: 0.84 | F4: 48250 | G4: 88000 | H4: 100500 | I4: 119750 | J4: 128000 | K4: 137500 | L4: 161000 | M4: 184250 | N4: 206250 | O4: 264000 | P4: 290250 | Q4: 316250 | R4: 350750 | S4: 401500
B5: TU DÍA | C5: L-V | D5: Off | E5: 1.71 | F5: 122500 | G5: 224000 | H5: 255500 | I5: 304500 | J5: 325500 | K5: 350000 | L5: 409500 | M5: 469000 | N5: 525000 | O5: 672000 | P5: 738500 | Q5: 805000 | R5: 892500 | S5: 1022000
B6: TELETRECE TARDE | C6: L-V | D6: Off | E6: 1.72 | F6: 131250 | G6: 240000 | H6: 273750 | I6: 326250 | J6: 348750 | K6: 375000 | L6: 438750 | M6: 502500 | N6: 562500 | O6: 720000 | P6: 791250 | Q6: 862500 | R6: 956250 | S6: 1095000
B7: EL TIEMPO TARDE | C7: L-V | D7: Off | E7: 1.64 | F7: 131250 | G7: 240000 | H7: 273750 | I7: 326250 | J7: 348750 | K7: 375000 | L7: 438750 | M7: 502500 | N7: 562500 | O7: 720000 | P7: 791250 | Q7: 862500 | R7: 956250 | S7: 1095000
B8: VALE TODO | C8: L-V | D8: Off | E8: 1.35 | F8: 78750 | G8: 144000 | H8: 164250 | I8: 195750 | J8: 209250 | K8: 225000 | L8: 263250 | M8: 301500 | N8: 337500 | O8: 432000 | P8: 474750 | Q8: 517500 | R8: 573750 | S8: 657000
B9: ALFOMBRA ROJA | C9: L-V | D9: Off | E9: 1.39 | F9: 140000 | G9: 256000 | H9: 292000 | I9: 348000 | J9: 372000 | K9: 400000 | L9: 468000 | M9: 536000 | N9: 600000 | O9: 768000 | P9: 844000 | Q9: 920000 | R9: 1020000 | S9: 1168000
B10: QUE DICE CHILE | C10: L-V | D10: Prime time | E10: 2.25 | F10: 210000 | G10: 384000 | H10: 438000 | I10: 522000 | J10: 558000 | K10: 600000 | L10: 702000 | M10: 804000 | N10: 900000 | O10: 1152000 | P10: 1266000 | Q10: 1380000 | R10: 1530000 | S10: 1752000
B11: TELETRECE | C11: L-V | D11: Prime time | E11: 2.77 | F11: 575750 | G11: 1052800 | H11: 1200850 | I11: 1431150 | J11: 1529850 | K11: 1645000 | L11: 1924650 | M11: 2204300 | N11: 2467500 | O11: 3158400 | P11: 3470950 | Q11: 3783500 | R11: 4194750 | S11: 4803400
B12: EL TIEMPO | C12: L-V | D12: Prime time | E12: 1.96 | F12: 575750 | G12: 1052800 | H12: 1200850 | I12: 1431150 | J12: 1529850 | K12: 1645000 | L12: 1924650 | M12: 2204300 | N12: 2467500 | O12: 3158400 | P12: 3470950 | Q12: 3783500 | R12: 4194750 | S12: 4803400
B13: VECINOS AL LÍMITE | C13: L-J | D13: Prime time | E13: 1.36 | F13: 175000 | G13: 320000 | H13: 365000 | I13: 435000 | J13: 465000 | K13: 500000 | L13: 585000 | M13: 670000 | N13: 750000 | O13: 960000 | P13: 1055000 | Q13: 1150000 | R13: 1275000 | S13: 1460000
B14: VÉRTIGO EXTREMO | C14: L | D14: Prime time | E14: 3.1 | F14: 612500 | G14: 1120000 | H14: 1277500 | I14: 1522500 | J14: 1627500 | K14: 1750000 | L14: 2047500 | M14: 2345000 | N14: 2625000 | O14: 3360000 | P14: 3692500 | Q14: 4025000 | R14: 4462500 | S14: 5110000
... B41: VERTIGO ESTELAR, REPETICIÓN | C41: D | D41: Off | E41: 0.45 | F41: 30750 | G41: 56000 | H41: 64000 | I41: 76250 | J41: 81500 | K41: 87500 | L41: 102500 | M41: 117250 | N41: 131250 | O41: 168000 | P41: 184750 | Q41: 201250 | R41: 223250 | S41: 255500
